2024-08-07 14:55:27,822 ERROR: Exception on /login [GET] [in /home/fabi/microblog/venv/lib/python3.10/site-packages/flask/app.py:1414]
Traceback (most recent call last):
  File "/home/fabi/microblog/venv/lib/python3.10/site-packages/flask/app.py", line 2190, in wsgi_app
    response = self.full_dispatch_request()
  File "/home/fabi/microblog/venv/lib/python3.10/site-packages/flask/app.py", line 1486, in full_dispatch_request
    rv = self.handle_user_exception(e)
  File "/home/fabi/microblog/venv/lib/python3.10/site-packages/flask/app.py", line 1484, in full_dispatch_request
    rv = self.dispatch_request()
  File "/home/fabi/microblog/venv/lib/python3.10/site-packages/flask/app.py", line 1469, in dispatch_request
    return self.ensure_sync(self.view_functions[rule.endpoint])(**view_args)
  File "/home/fabi/microblog/app/routes.py", line 62, in login
    return render_template('login.html', title='Sing In', form=form)
  File "/home/fabi/microblog/venv/lib/python3.10/site-packages/flask/templating.py", line 151, in render_template
    return _render(app, template, context)
  File "/home/fabi/microblog/venv/lib/python3.10/site-packages/flask/templating.py", line 132, in _render
    rv = template.render(context)
  File "/home/fabi/microblog/venv/lib/python3.10/site-packages/jinja2/environment.py", line 1304, in render
    self.environment.handle_exception()
  File "/home/fabi/microblog/venv/lib/python3.10/site-packages/jinja2/environment.py", line 939, in handle_exception
    raise rewrite_traceback_stack(source=source)
  File "/home/fabi/microblog/app/templates/login.html", line 2, in top-level template code
    {% import "bootstrap_wtf.html" as wtf %}
  File "/home/fabi/microblog/app/templates/base.html", line 75, in top-level template code
    {% block content %}{% endblock %}
  File "/home/fabi/microblog/app/templates/login.html", line 7, in block 'content'
    <p>{{ ('New User?') }} <a href="{{ url_for('auth.register') }}">{{ ('Click to Register!') }}</a></p>
  File "/home/fabi/microblog/venv/lib/python3.10/site-packages/flask/app.py", line 1697, in url_for
    return self.handle_url_build_error(error, endpoint, values)
  File "/home/fabi/microblog/venv/lib/python3.10/site-packages/flask/app.py", line 1686, in url_for
    rv = url_adapter.build(  # type: ignore[union-attr]
  File "/home/fabi/microblog/venv/lib/python3.10/site-packages/werkzeug/routing/map.py", line 950, in build
    raise BuildError(endpoint, values, method, self)
werkzeug.routing.exceptions.BuildError: Could not build url for endpoint 'auth.register'. Did you mean 'register' instead?
2024-08-07 15:08:10,350 INFO: Microblog startup [in /home/fabi/microblog/app/__init__.py:49]
2024-08-07 15:08:40,550 ERROR: Exception on /index [GET] [in /home/fabi/microblog/venv/lib/python3.10/site-packages/flask/app.py:1414]
Traceback (most recent call last):
  File "/home/fabi/microblog/venv/lib/python3.10/site-packages/flask/app.py", line 2190, in wsgi_app
    response = self.full_dispatch_request()
  File "/home/fabi/microblog/venv/lib/python3.10/site-packages/flask/app.py", line 1486, in full_dispatch_request
    rv = self.handle_user_exception(e)
  File "/home/fabi/microblog/venv/lib/python3.10/site-packages/flask/app.py", line 1484, in full_dispatch_request
    rv = self.dispatch_request()
  File "/home/fabi/microblog/venv/lib/python3.10/site-packages/flask/app.py", line 1469, in dispatch_request
    return self.ensure_sync(self.view_functions[rule.endpoint])(**view_args)
  File "/home/fabi/microblog/venv/lib/python3.10/site-packages/flask_login/utils.py", line 290, in decorated_view
    return current_app.ensure_sync(func)(*args, **kwargs)
  File "/home/fabi/microblog/app/routes.py", line 42, in index
    return render_template('index.html', title='Home', form=form, posts=posts.items, next_url=next_url, prev_url=prev_url)
  File "/home/fabi/microblog/venv/lib/python3.10/site-packages/flask/templating.py", line 150, in render_template
    template = app.jinja_env.get_or_select_template(template_name_or_list)
  File "/home/fabi/microblog/venv/lib/python3.10/site-packages/jinja2/environment.py", line 1084, in get_or_select_template
    return self.get_template(template_name_or_list, parent, globals)
  File "/home/fabi/microblog/venv/lib/python3.10/site-packages/jinja2/environment.py", line 1013, in get_template
    return self._load_template(name, globals)
  File "/home/fabi/microblog/venv/lib/python3.10/site-packages/jinja2/environment.py", line 972, in _load_template
    template = self.loader.load(self, name, self.make_globals(globals))
  File "/home/fabi/microblog/venv/lib/python3.10/site-packages/jinja2/loaders.py", line 138, in load
    code = environment.compile(source, name, filename)
  File "/home/fabi/microblog/venv/lib/python3.10/site-packages/jinja2/environment.py", line 768, in compile
    self.handle_exception(source=source_hint)
  File "/home/fabi/microblog/venv/lib/python3.10/site-packages/jinja2/environment.py", line 939, in handle_exception
    raise rewrite_traceback_stack(source=source)
  File "/home/fabi/microblog/app/templates/index.html", line 5, in template
    <h1>{{ ('Hi, %(username)s!', username=current_user.username) }}</h1>
jinja2.exceptions.TemplateSyntaxError: expected token ')', got '='
2024-08-07 15:16:34,094 INFO: Microblog startup [in /home/fabi/microblog/app/__init__.py:49]
2024-08-07 15:16:36,050 ERROR: Exception on / [GET] [in /home/fabi/microblog/venv/lib/python3.10/site-packages/flask/app.py:1414]
Traceback (most recent call last):
  File "/home/fabi/microblog/venv/lib/python3.10/site-packages/flask/app.py", line 2190, in wsgi_app
    response = self.full_dispatch_request()
  File "/home/fabi/microblog/venv/lib/python3.10/site-packages/flask/app.py", line 1486, in full_dispatch_request
    rv = self.handle_user_exception(e)
  File "/home/fabi/microblog/venv/lib/python3.10/site-packages/flask/app.py", line 1484, in full_dispatch_request
    rv = self.dispatch_request()
  File "/home/fabi/microblog/venv/lib/python3.10/site-packages/flask/app.py", line 1469, in dispatch_request
    return self.ensure_sync(self.view_functions[rule.endpoint])(**view_args)
  File "/home/fabi/microblog/venv/lib/python3.10/site-packages/flask_login/utils.py", line 290, in decorated_view
    return current_app.ensure_sync(func)(*args, **kwargs)
  File "/home/fabi/microblog/app/routes.py", line 42, in index
    return render_template('index.html', title='Home', form=form, posts=posts.items, next_url=next_url, prev_url=prev_url)
  File "/home/fabi/microblog/venv/lib/python3.10/site-packages/flask/templating.py", line 150, in render_template
    template = app.jinja_env.get_or_select_template(template_name_or_list)
  File "/home/fabi/microblog/venv/lib/python3.10/site-packages/jinja2/environment.py", line 1084, in get_or_select_template
    return self.get_template(template_name_or_list, parent, globals)
  File "/home/fabi/microblog/venv/lib/python3.10/site-packages/jinja2/environment.py", line 1013, in get_template
    return self._load_template(name, globals)
  File "/home/fabi/microblog/venv/lib/python3.10/site-packages/jinja2/environment.py", line 972, in _load_template
    template = self.loader.load(self, name, self.make_globals(globals))
  File "/home/fabi/microblog/venv/lib/python3.10/site-packages/jinja2/loaders.py", line 138, in load
    code = environment.compile(source, name, filename)
  File "/home/fabi/microblog/venv/lib/python3.10/site-packages/jinja2/environment.py", line 768, in compile
    self.handle_exception(source=source_hint)
  File "/home/fabi/microblog/venv/lib/python3.10/site-packages/jinja2/environment.py", line 939, in handle_exception
    raise rewrite_traceback_stack(source=source)
  File "/home/fabi/microblog/app/templates/index.html", line 5, in template
    <h1>{{ ('Hi, %(username)s!', username=current_user.username) }}</h1>
jinja2.exceptions.TemplateSyntaxError: expected token ')', got '='
2024-08-07 15:17:06,792 INFO: Microblog startup [in /home/fabi/microblog/app/__init__.py:49]
